Workbook

Sheet Tổng hợp
A1: Tổng hợp case UAT theo tác nhân và loại
A2: Nguồn: bản đồ MOE Education Account và FAS, e-Service luồng mới (userflow đề xuất 24/10/2026). Các số bên dưới tự tính từ sheet Danh sách case.
A4: Tác nhân | B4: Positive | C4: Negative | D4: Alternative | E4: Edge | F4: Tổng
A5: MOE HQ | B5: =COUNTIFS('Danh sách case'!$B$2:$B$46,$A5,'Danh sách case'!$C$2:$C$46,B$4) -> 6 | C5: =COUNTIFS('Danh sách case'!$B$2:$B$46,$A5,'Danh sách case'!$C$2:$C$46,C$4) -> 6 | D5: =COUNTIFS('Danh sách case'!$B$2:$B$46,$A5,'Danh sách case'!$C$2:$C$46,D$4) -> 1 | E5: =COUNTIFS('Danh sách case'!$B$2:$B$46,$A5,'Danh sách case'!$C$2:$C$46,E$4) -> 3 | F5: =SUM(B5:E5) -> 16
A6: School user | B6: =COUNTIFS('Danh sách case'!$B$2:$B$46,$A6,'Danh sách case'!$C$2:$C$46,B$4) -> 4 | C6: =COUNTIFS('Danh sách case'!$B$2:$B$46,$A6,'Danh sách case'!$C$2:$C$46,C$4) -> 3 | D6: =COUNTIFS('Danh sách case'!$B$2:$B$46,$A6,'Danh sách case'!$C$2:$C$46,D$4) -> 0 | E6: =COUNTIFS('Danh sách case'!$B$2:$B$46,$A6,'Danh sách case'!$C$2:$C$46,E$4) -> 2 | F6: =SUM(B6:E6) -> 9
A7: Parent | B7: =COUNTIFS('Danh sách case'!$B$2:$B$46,$A7,'Danh sách case'!$C$2:$C$46,B$4) -> 3 | C7: =COUNTIFS('Danh sách case'!$B$2:$B$46,$A7,'Danh sách case'!$C$2:$C$46,C$4) -> 8 | D7: =COUNTIFS('Danh sách case'!$B$2:$B$46,$A7,'Danh sách case'!$C$2:$C$46,D$4) -> 4 | E7: =COUNTIFS('Danh sách case'!$B$2:$B$46,$A7,'Danh sách case'!$C$2:$C$46,E$4) -> 5 | F7: =SUM(B7:E7) -> 20
A8: Tổng | B8: =SUM(B5:B7) -> 13 | C8: =SUM(C5:C7) -> 17 | D8: =SUM(D5:D7) -> 5 | E8: =SUM(E5:E7) -> 10 | F8: =SUM(F5:F7) -> 45
A10: Kết quả test
A11: Trạng thái | B11: Số case | C11: Tỷ lệ
A12: Chưa test | B12: =COUNTIF('Danh sách case'!$L$2:$L$46,A12) -> 45 | C12: =IF($F$8=0,0,B12/$F$8) -> 1
A13: Pass | B13: =COUNTIF('Danh sách case'!$L$2:$L$46,A13) -> 0 | C13: =IF($F$8=0,0,B13/$F$8) -> 0
A14: Fail | B14: =COUNTIF('Danh sách case'!$L$2:$L$46,A14) -> 0 | C14: =IF($F$8=0,0,B14/$F$8) -> 0
A15: Blocked | B15: =COUNTIF('Danh sách case'!$L$2:$L$46,A15) -> 0 | C15: =IF($F$8=0,0,B15/$F$8) -> 0
A17: Ghi chú: nhánh Alternative, Edge và Negative đều gắn với một luồng Positive qua cột Nhánh của. FS07 không có trong thư mục nên chưa có case nào cho R7.

Sheet Danh sách case
A1: UAT ID | B1: Tác nhân | C1: Loại | D1: Nhánh của | E1: Rẽ nhánh tại | F1: Tên case | G1: Các bước | H1: Kết quả mong đợi | I1: FS tham chiếu | J1: Test data | K1: Người test | L1: Trạng thái | M1: Ghi chú
A2: UAT-MOE-01 | B2: MOE HQ | C2: Positive | F2: Chuẩn bị EA, trường, học sinh và phát hành phí | G2: 1. Job đồng bộ hằng ngày: Job đồng bộ tạo EA cho học sinh vừa đủ 7 tuổi 2. Tạo Education Account tự động: EA Active, số dư SGD 0.00 3. HQ mở màn quản lý School: HQ mở màn quản lý School 4. Quản lý trường, lớp, học sinh: Tạo School, School User; trường nhập học sinh và gán lớp 5. Liên kết học sinh với EA: Học sinh Singaporean được liên kết với EA 6. Cấu hình loại phí, component, mức phí: Cấu hình loại phí, component, mức phí 7. Phát hành phí và tìm người nhận: Phát hành phí, tìm học sinh nhận phí 8. Sinh và quản lý Student Charge: Sinh Student Charge POSTED, hiện cho phụ huynh | H2: Sinh Student Charge POSTED, hiện cho phụ huynh | I2: FS01.md, FS03.md | L2: Chưa test
A3: UAT-MOE-01-N1 | B3: MOE HQ | C3: Negative | D3: UAT-MOE-01 | E3: Tạo Education Account tự động | F3: Công dân không đủ điều kiện tạo EA | G3: 1. Tạo Education Account tự động: Không phải công dân, ngoài độ tuổi, thiếu dữ liệu hoặc đã có EA 2. Không tạo EA: Bỏ qua bản ghi, không tạo EA | H3: Bỏ qua bản ghi, không tạo EA | I3: FS01.md | L3: Chưa test
A4: UAT-MOE-01-N2 | B4: MOE HQ | C4: Negative | D4: UAT-MOE-01 | E4: Liên kết học sinh với EA | F4: Học sinh chưa có EA để liên kết | G4: 1. Liên kết học sinh với EA: Học sinh Singaporean nhưng EA chưa có hoặc đã đóng 2. Chưa liên kết được EA: Chưa liên kết, cách xử lý chờ khách hàng chốt | H4: Chưa liên kết, cách xử lý chờ khách hàng chốt | I4: FS03.md | L4: Chưa test
A5: UAT-MOE-02 | B5: MOE HQ | C5: Positive | F5: Top-up lẻ cho một EA | G5: 1. HQ User mở menu Top-up: HQ User mở tab Individual Top-Up 2. Tìm và xác minh chủ tài khoản: Nhập NRIC đầy đủ, thấy chủ tài khoản, EA Active, số dư 3. Top-up lẻ cho một EA: Nhập 50.00, xem lại, xác nhận 4. Top-up thành công: Số dư tăng đúng 50.00 một lần, có Reference và audit | H5: Số dư tăng đúng 50.00 một lần, có Reference và audit | I5: FS02.md | L5: Chưa test
A6: UAT-MOE-02-N1 | B6: MOE HQ | C6: Negative | D6: UAT-MOE-02 | E6: Tìm và xác minh chủ tài khoản | F6: Không tìm thấy EA | G6: 1. Tìm và xác minh chủ tài khoản: NRIC thiếu ký tự hoặc không có EA 2. Không tìm thấy EA: Báo MSG-0201, không hiện gợi ý nào | H6: Báo MSG-0201, không hiện gợi ý nào | I6: FS02.md | L6: Chưa test
A7: UAT-MOE-02-N2 | B7: MOE HQ | C7: Negative | D7: UAT-MOE-02 | E7: Top-up lẻ cho một EA | F7: EA đã Closed | G7: 1. Top-up lẻ cho một EA: Xác nhận top-up cho EA không còn Active 2. Top-up thất bại: Bị từ chối, số dư không đổi, transaction Failed được ghi log | H7: Bị từ chối, số dư không đổi, transaction Failed được ghi log | I7: FS02.md | L7: Chưa test
A8: UAT-MOE-02-E1 | B8: MOE HQ | C8: Edge | D8: UAT-MOE-02 | E8: Top-up lẻ cho một EA | F8: Bấm xác nhận hai lần | G8: 1. Top-up lẻ cho một EA: HQ User bấm xác nhận hai lần liên tiếp 2. Top-up thành công: Chỉ một transaction theo Reference ID, ghi có một lần | H8: Chỉ một transaction theo Reference ID, ghi có một lần | I8: FS02.md | L8: Chưa test
A9: UAT-MOE-03 | B9: MOE HQ | C9: Positive | F9: Tạo và chạy Campaign top-up hàng loạt | G9: 1. HQ User mở menu Top-up: HQ User mở tab Bulk Campaigns 2. Cấu hình Campaign: Tạo campaign tuổi 7 đến 12, số dư dưới 100, 100.00 mỗi tài khoản 3. Preview danh sách eligible: Preview thấy số tài khoản và tổng tiền dự kiến 4. Run Campaign: Bấm Run Campaign, batch Pending rồi Running 5. Thực thi batch và theo dõi: Ghi có từng EA, đánh giá lại criterion lúc xử lý 6. Batch Completed: Cả batch Successful, Batches Run tăng 1 | H9: Cả batch Successful, Batches Run tăng 1 | I9: FS02.md | L9: Chưa test
A10: UAT-MOE-03-N1 | B10: MOE HQ | C10: Negative | D10: UAT-MOE-03 | E10: Run Campaign | F10: Không có tài khoản eligible | G10: 1. Run Campaign: Không EA nào thỏa criterion lúc bấm Run Campaign 2. Không có tài khoản eligible: Báo MSG-0214, không tạo batch | H10: Báo MSG-0214, không tạo batch | I10: FS02.md | L10: Chưa test
A11: UAT-MOE-03-A1 | B11: MOE HQ | C11: Alternative | D11: UAT-MOE-03 | E11: Thực thi batch và theo dõi | F11: Một số EA bị Failed trong batch | G11: 1. Thực thi batch và theo dõi: Một EA bị đóng hoặc không còn thỏa criterion lúc xử lý 2. Batch Failed: EA đó Failed, số dư không đổi, các EA khác vẫn được ghi có | H11: EA đó Failed, số dư không đổi, các EA khác vẫn được ghi có | I11: FS02.md | L11: Chưa test
A12: UAT-MOE-03-E1 | B12: MOE HQ | C12: Edge | D12: UAT-MOE-03 | E12: Thực thi batch và theo dõi | F12: Server khởi động lại giữa batch | G12: 1. Thực thi batch và theo dõi: Server restart khi batch đang Running 2. Batch Completed: Batch tiếp tục từ item chưa xử lý, không ghi có trùng | H12: Batch tiếp tục từ item chưa xử lý, không ghi có trùng | I12: FS02.md | L12: Chưa test
A13: UAT-MOE-04 | B13: MOE HQ | C13: Positive | F13: Thiết lập ngân sách MOEFAS | G13: 1. User mở Budget và Statistics: MOE HQ mở Manage Budget 2. Thiết lập và xem ngân sách: Nhập Budget Amount, bấm Save 3. Ngân sách đã lưu: Hiện Budget Amount đã lưu | H13: Hiện Budget Amount đã lưu | I13: FS06.md | L13: Chưa test
A14: UAT-MOE-05 | B14: MOE HQ | C14: Positive | F14: Theo dõi thống kê và sử dụng ngân sách MOEFAS | G14: 1. User mở Budget và Statistics: MOE HQ mở Budget Tracking 2. Thống kê subsidy đã granted: Lấy tổng subsidy đã granted trong phạm vi MOEFAS 3. Theo dõi sử dụng ngân sách: Hiện Budget Amount, Subsidy Amount Used, Remaining Budget | H14: Hiện Budget Amount, Subsidy Amount Used, Remaining Budget | I14: FS06.md | L14: Chưa test
A15: UAT-MOE-05-E1 | B15: MOE HQ | C15: Edge | D15: UAT-MOE-05 | E15: Theo dõi sử dụng ngân sách | F15: Budget hết nhưng vẫn grant | G15: 1. Theo dõi sử dụng ngân sách: Subsidy Amount Used chạm hoặc vượt Budget Amount 2. Cảnh báo hết budget, vẫn grant: Hiện cảnh báo, không chặn grant | H15: Hiện cảnh báo, không chặn grant | I15: FS06.md | L15: Chưa test
A16: UAT-MOE-06 | B16: MOE HQ | C16: Positive | F16: Tạo scheme MOEFAS và xem đơn FAS | G16: 1. Admin mở Financial assistance: MOE HQ mở MOEFAS schemes 2. Quản lý scheme FAS: Wizard General, Eligibility, Subsidy theo cấp rồi Publish 3. Danh sách đơn FAS: Xem đơn FAS của mọi trường, chỉ xem, không Approve hay Reject | H16: Xem đơn FAS của mọi trường, chỉ xem, không Approve hay Reject | I16: FS04.md | L16: Chưa test
A17: UAT-MOE-06-N1 | B17: MOE HQ | C17: Negative | D17: UAT-MOE-06 | E17: Quản lý scheme FAS | F17: Scheme không hợp lệ | G17: 1. Quản lý scheme FAS: Effective from bằng hoặc trước Form closes, hoặc kỳ chồng scheme khác 2. Scheme không hợp lệ, không publish được: Báo lỗi, không publish được | H17: Báo lỗi, không publish được | I17: FS04.md | L17: Chưa test
A18: UAT-SCH-01 | B18: School user | C18: Positive | F18: Nhập đơn giấy của phụ huynh | G18: 1. School user mở Upload applications: School user mở Upload applications 2. Upload scans và đọc bản scan: Tải bản scan, hệ thống đọc mẫu đơn 3. Review application, Part 1 đến 5: Nhập NRIC, thông tin tự điền, thu nhập từ dữ liệu Chính phủ 4. Kiểm tra hợp lệ trước khi nộp: Review and submit, form đang mở, dữ liệu hợp lệ 5. Review before submitting và nộp: Confirm and submit, mỗi con một đơn 6. Phân luồng đơn lúc nộp: Phân luồng theo F4 7. Đơn MOEFAS chờ form đóng: MOEFAS Pending chờ form đóng | H18: MOEFAS Pending chờ form đóng | I18: FS05.md, FS04.md | L18: Chưa test
A19: UAT-SCH-01-N1 | B19: School user | C19: Negative | D19: UAT-SCH-01 | E19: Kiểm tra hợp lệ trước khi nộp | F19: Bị chặn khi nộp đơn giấy | G19: 1. Kiểm tra hợp lệ trước khi nộp: Thiếu trường, con ngoài 7 đến 16 tuổi, đã có đơn, trùng NRIC, hoặc form đã đóng 2. Bị chặn khi nộp: Ghi chú đỏ liệt kê điều cần sửa, không tạo đơn | H19: Ghi chú đỏ liệt kê điều cần sửa, không tạo đơn | I19: FS05.md | L19: Chưa test
A20: UAT-SCH-01-E1 | B20: School user | C20: Edge | D20: UAT-SCH-01 | E20: Review application, Part 1 đến 5 | F20: Lưu nháp khi nhập dở | G20: 1. Review application, Part 1 đến 5: Bấm Save draft 2. Bản nháp đã lưu: Dòng Draft hiện trong danh sách, Continue hoặc Delete | H20: Dòng Draft hiện trong danh sách, Continue hoặc Delete | I20: FS05.md, FS10.md | L20: Chưa test
A21: UAT-SCH-02 | B21: School user | C21: Positive | F21: Tạo scheme SBFAS và thêm fee | G21: 1. Admin mở Financial assistance: School Admin mở SBFAS schemes 2. Quản lý scheme FAS: Wizard General, Eligibility, Subsidy rồi Publish Tier 1 3. Add fee vào scheme đã publish: Thêm fee component phát sinh cuối năm vào scheme Active 4. Áp trợ cấp sau quyết định: Áp trợ cấp cho phí đang mở của học sinh đã được cấp | H21: Áp trợ cấp cho phí đang mở của học sinh đã được cấp | I21: FS04.md | L21: Chưa test
A22: UAT-SCH-02-N1 | B22: School user | C22: Negative | D22: UAT-SCH-02 | E22: Quản lý scheme FAS | F22: Scheme SBFAS không hợp lệ | G22: 1. Quản lý scheme FAS: Effective from không sau Form closes, hoặc kỳ chồng với Tier cùng tên 2. Scheme không hợp lệ, không publish được: Báo lỗi, không publish được | H22: Báo lỗi, không publish được | I22: FS04.md | L22: Chưa test
A23: UAT-SCH-03 | B23: School user | C23: Positive | F23: Duyệt đơn SBFAS | G23: 1. Admin mở Financial assistance: School Admin mở FAS applications, tab Pending 2. Danh sách đơn FAS: Mở đơn SBFAS của học sinh trong trường 3. Trường duyệt hoặc từ chối SBFAS: Chọn tier ML gợi ý, bấm Approve 4. Áp trợ cấp sau quyết định: Áp trợ cấp theo khối của học sinh 5. Đơn Approved: Approved kèm tier, Effective from của scheme | H23: Approved kèm tier, Effective from của scheme | I23: FS04.md | L23: Chưa test
A24: UAT-SCH-03-N1 | B24: School user | C24: Negative | D24: UAT-SCH-03 | E24: Trường duyệt hoặc từ chối SBFAS | F24: Từ chối đơn SBFAS | G24: 1. Trường duyệt hoặc từ chối SBFAS: Chọn Reject, điền Reason và Comment 2. Đơn Rejected: Rejected, phụ huynh nhận email lý do | H24: Rejected, phụ huynh nhận email lý do | I24: FS04.md | L24: Chưa test
A25: UAT-SCH-04 | B25: School user | C25: Positive | F25: Thiết lập và theo dõi ngân sách SBFAS | G25: 1. User mở Budget và Statistics: School user mở Manage Budget 2. Thiết lập và xem ngân sách: Nhập Budget Amount SBFAS của trường, Save 3. Theo dõi sử dụng ngân sách: Theo dõi Subsidy Amount Used và Remaining Budget của trường | H25: Theo dõi Subsidy Amount Used và Remaining Budget của trường | I25: FS06.md | L25: Chưa test
A26: UAT-SCH-04-E1 | B26: School user | C26: Edge | D26: UAT-SCH-04 | E26: Theo dõi sử dụng ngân sách | F26: Budget SBFAS hết nhưng vẫn grant | G26: 1. Theo dõi sử dụng ngân sách: Subsidy Amount Used chạm hoặc vượt Budget Amount 2. Cảnh báo hết budget, vẫn grant: Hiện cảnh báo, không chặn grant | H26: Hiện cảnh báo, không chặn grant | I26: FS06.md | L26: Chưa test
A27: UAT-PAR-01 | B27: Parent | C27: Positive | F27: Đăng nhập, xem EA và trả phí bằng EA | G27: 1. Parent mở e-Service: Parent mở e-Service 2. Đăng nhập SingPass: Đăng nhập SingPass, API tìm thấy Parent và con 3. Home và xem EA của con: Home hiện thẻ Edu Account của con, số dư EA 4. Edu Account Detail, điểm bắt đầu của từng con: Chọn thẻ con, mở Edu Account Detail 5. Xem invoice chưa trả: Chọn Trả phí, thấy invoice Issued của đúng con 6. Chọn cách thanh toán: Số dư đủ, Parent chọn trả bằng EA 7. Trả bằng EA: Closure check qua, sổ cái trừ EA đúng một lần 8. Kết quả, biên lai, hoàn EA: Mọi nhánh Succeeded 9. Invoice đã thanh toán: Invoice Paid, có mã tham chiếu và biên lai | H27: Invoice Paid, có mã tham chiếu và biên lai | I27: FS08.md, FS09.md | L27: Chưa test
A28: UAT-PAR-01-N1 | B28: Parent | C28: Negative | D28: UAT-PAR-01 | E28: Đăng nhập SingPass | F28: SingPass lỗi hoặc Parent hủy | G28: 1. Đăng nhập SingPass: SingPass báo lỗi hoặc Parent bấm hủy 2. Đăng nhập không xong: Báo MSG-0802, quay lại trang đăng nhập | H28: Báo MSG-0802, quay lại trang đăng nhập | I28: FS08.md | L28: Chưa test
A29: UAT-PAR-01-N2 | B29: Parent | C29: Negative | D29: UAT-PAR-01 | E29: Đăng nhập SingPass | F29: Không tìm thấy Parent hoặc API chậm | G29: 1. Đăng nhập SingPass: API không thấy Parent, Parent không có con, hoặc quá 10 giây 2. Không vào được hệ thống: Báo MSG-0801 hoặc MSG-0809, không vào được | H29: Báo MSG-0801 hoặc MSG-0809, không vào được | I29: FS08.md | L29: Chưa test
A30: UAT-PAR-01-E1 | B30: Parent | C30: Edge | D30: UAT-PAR-01 | E30: Home và xem EA của con | F30: Con vừa đủ 16 tuổi | G30: 1. Home và xem EA của con: Parent mở EA của con vừa đủ 16 tuổi 2. Kiểm tra và đóng EA: Closure check: đủ 16 tuổi, EA ở trạng thái Due for closure 3. Con đủ 16 tuổi: Chỉ xem, không thanh toán, không nộp FAS | H30: Chỉ xem, không thanh toán, không nộp FAS | I30: FS08.md, FS01.md | L30: Chưa test
A31: UAT-PAR-01-N3 | B31: Parent | C31: Negative | D31: UAT-PAR-01 | E31: Chọn cách thanh toán | F31: Không đủ số dư cho lựa chọn chỉ EA | G31: 1. Chọn cách thanh toán: Số dư EA nhỏ hơn số phải trả 2. Không đủ số dư: Hiện lý do, gợi ý trả online hoặc chia đôi | H31: Hiện lý do, gợi ý trả online hoặc chia đôi | I31: FS09.md | L31: Chưa test
A32: UAT-PAR-01-A1 | B32: Parent | C32: Alternative | D32: UAT-PAR-01 | E32: Chọn cách thanh toán | F32: Chia đôi EA và online | G32: 1. Chọn cách thanh toán: Số dư 20.00, invoice 50.00: chọn chia đôi 2. Trả bằng EA: Trừ trước phần EA 20.00 3. Trả online và nhận kết quả: Mở phiên online cho 30.00, webhook báo thành công 4. Kết quả, biên lai, hoàn EA: Cả hai nhánh Succeeded 5. Invoice đã thanh toán: Invoice Paid, biên lai ghi cả hai phần | H32: Invoice Paid, biên lai ghi cả hai phần | I32: FS09.md | L32: Chưa test
A33: UAT-PAR-01-N4 | B33: Parent | C33: Negative | D33: UAT-PAR-01-A1 | E33: Trả online và nhận kết quả | F33: Phần online thất bại | G33: 1. Trả online và nhận kết quả: Online thất bại, bị hủy hoặc hết hạn 2. Kết quả, biên lai, hoàn EA: Gọi Function 1 hoàn phần EA, nhánh EA Reversed 3. Invoice về Issued: Invoice về Issued, cho thử lại | H33: Invoice về Issued, cho thử lại | I33: FS09.md | L33: Chưa test
A34: UAT-PAR-01-E2 | B34: Parent | C34: Edge | D34: UAT-PAR-01-N4 | E34: Kết quả, biên lai, hoàn EA | F34: Hoàn EA bị lỗi | G34: 1. Kết quả, biên lai, hoàn EA: Lệnh hoàn EA thất bại 2. Chờ vận hành xử lý: ReconciliationRequired, cảnh báo vận hành | H34: ReconciliationRequired, cảnh báo vận hành | I34: FS09.md | L34: Chưa test
A35: UAT-PAR-03 | B35: Parent | C35: Positive | F35: Xem hoạt động EA của một con | G35: 1. Parent mở e-Service: Parent mở e-Service 2. Đăng nhập SingPass: Đăng nhập SingPass 3. Home và xem EA của con: Home hiện thẻ Edu Account của các con 4. Edu Account Detail, điểm bắt đầu của từng con: Chọn thẻ con, mở Edu Account Detail 5. Hoạt động số dư EA của một con: Xem ghi có, ghi nợ ví của con này | H35: Xem ghi có, ghi nợ ví của con này | I35: FS08.md | L35: Chưa test
A36: UAT-PAR-03-A1 | B36: Parent | C36: Alternative | D36: UAT-PAR-03 | E36: Home và xem EA của con | F36: Xem gộp hoạt động EA của các con | G36: 1. Home và xem EA của con: Bấm Hoạt động EA gần đây của các con 2. Hoạt động EA gần đây của các con: Mỗi dòng có tên con và mã EA 3. Edu Account Detail, điểm bắt đầu của từng con: Chọn tên con, sang Edu Account Detail của con đó | H36: Chọn tên con, sang Edu Account Detail của con đó | I36: FS08.md | L36: Chưa test
A37: UAT-PAR-03-E1 | B37: Parent | C37: Edge | D37: UAT-PAR-03 | E37: Edu Account Detail, điểm bắt đầu của từng con | F37: Hóa đơn và thanh toán (tương lai) | G37: 1. Edu Account Detail, điểm bắt đầu của từng con: Nhánh nét đứt, chưa hiện menu 2. Hóa đơn và thanh toán (tương lai): Mỗi invoice một dòng, mở ra thấy EA 60 + Online 40 trong cùng payment | H37: Mỗi invoice một dòng, mở ra thấy EA 60 + Online 40 trong cùng payment | I37: FS08.md, FS09.md | L37: Chưa test
A38: UAT-PAR-02 | B38: Parent | C38: Positive | F38: Nộp đơn FAS online, MOEFAS tự duyệt sau khi form đóng | G38: 1. Parent mở e-Service: Parent mở e-Service 2. Đăng nhập SingPass: Đăng nhập SingPass 3. Home và xem EA của con: Home hiện card của con 4. Trang Financial assistance và bản nháp: Mở Financial assistance, bấm Apply for FAS 5. Bước 1 Children: Chọn quan hệ và con, thông tin phụ huynh tự điền 6. Bước 2 Household và thu nhập: Thu nhập tự lấy từ dữ liệu Chính phủ, hiện GHI và PCI 7. Bước 3 Documents và bước 4 Context: Bỏ qua tài liệu, nhập context 8. Bước 5 Review và Submit: Tick xác nhận, Submit application 9. Phân luồng đơn lúc nộp: MOEFAS Pending, System check Waiting 10. Form MOEFAS đóng: Form MOEFAS đóng 11. Xếp hạng và duyệt MOEFAS tự động: Xếp hạng theo PCI thấp nhất, đơn đạt điều kiện 12. Áp trợ cấp sau quyết định: Áp trợ cấp theo cấp của học sinh 13. Đơn Approved: Approved MOEFAS, phụ huynh nhận email | H38: Approved MOEFAS, phụ huynh nhận email | I38: FS08.md, FS10.md, FS04.md | L38: Chưa test
A39: UAT-PAR-02-N1 | B39: Parent | C39: Negative | D39: UAT-PAR-02 | E39: Bước 1 Children | F39: Con bị khoá khi chọn | G39: 1. Bước 1 Children: Con đã 16 tuổi, đã có đơn đang xét, hoặc form đã đóng 2. Con bị khoá hoặc không nộp được: Con bị khoá, Continue không bật | H39: Con bị khoá, Continue không bật | I39: FS10.md | L39: Chưa test
A40: UAT-PAR-02-N2 | B40: Parent | C40: Negative | D40: UAT-PAR-02 | E40: Trang Financial assistance và bản nháp | F40: Không có form FAS nào đang mở | G40: 1. Trang Financial assistance và bản nháp: Mọi con từ 16 tuổi, đã có đơn Pending, hoặc không có form đang mở 2. Con bị khoá hoặc không nộp được: Apply for FAS bị khoá, hiện ngày form kế tiếp | H40: Apply for FAS bị khoá, hiện ngày form kế tiếp | I40: FS10.md | L40: Chưa test
...

Sheet Hướng dẫn
A1: Cách dùng file
A3: Ô vàng | B3: Là ô cần điền: Test data, Người test, Trạng thái, Ghi chú. Các cột còn lại lấy từ bản đồ nên không sửa tay.
A4: UAT ID | B4: Cùng mã với tên kịch bản trong MapApp. Khi client xem bản đồ, tra mã này sang đây để thấy bước và test data.
A5: Các bước | B5: Mỗi dòng là một khối trên bản đồ kèm ghi chú ngắn. Case nhánh chỉ có các bước từ chỗ rẽ nhánh, bước trước đó nằm ở case cha (cột Nhánh của).
A6: Kết quả mong đợi | B6: Lấy từ ghi chú của bước cuối. Cần đối chiếu thêm với AC trong FS khi viết case chi tiết.
A7: Test data | B7: Để trống, điền theo từng user test. Nên ghi theo dạng: tài khoản, NRIC hoặc mã EA, số dư, trạng thái ban đầu.
A9: Dòng ví dụ định dạng test data (chỉ để minh họa, không phải dữ liệu thật)
A10: UAT ID | B10: Test data | C10: Người test | D10: Trạng thái
A11: UAT-PAR-01 | B11: Parent: NRIC S0000000A, con A: EA-001, số dư SGD 100, invoice Issued SGD 50 | C11: Tên người test | D11: Chưa test
